{"uuid": "160f2190-a3a4-453f-8aca-e29266ad1548", "children": ["ef642b7a-de82-454f-92e6-0de7ade60614"], "befores": [{"name": "emulator_1", "status": "broken", "statusDetails": {"message": "selenium.common.exceptions.WebDriverException: Message: An unknown server-side error occurred while processing the command. Original error: Could not find a driver for automationName 'UiAutomator2' and platformName 'Android'. Have you installed a driver that supports those capabilities? Run 'appium driver list --installed' to see. (Lower-level error: Could not find installed driver to support given caps)\nStacktrace:\nUnknownError: An unknown server-side error occurred while processing the command. Original error: Could not find a driver for automationName 'UiAutomator2' and platformName 'Android'. Have you installed a driver that supports those capabilities? Run 'appium driver list --installed' to see. (Lower-level error: Could not find installed driver to support given caps)\n    at getResponseForW3CError (/usr/local/lib/node_modules/appium/node_modules/@appium/base-driver/lib/protocol/errors.js:1098:4)\n    at asyncHandler (/usr/local/lib/node_modules/appium/node_modules/@appium/base-driver/lib/protocol/protocol.js:491:57)\n", "trace": "  File \"/Users/mx13/Desktop/tpay_automation/myenv/lib/python3.11/site-packages/pluggy/_callers.py\", line 77, in _multicall\n    res = hook_impl.function(*args)\n          ^^^^^^^^^^^^^^^^^^^^^^^^^\n  File \"/Users/mx13/Desktop/tpay_automation/myenv/lib/python3.11/site-packages/_pytest/fixtures.py\", line 1123, in pytest_fixture_setup\n    result = call_fixture_func(fixturefunc, request, kwargs)\n             ^^^^^^^^^^^^^^^^^^^^^^^^^^^^^^^^^^^^^^^^^^^^^^^\n  File \"/Users/mx13/Desktop/tpay_automation/myenv/lib/python3.11/site-packages/_pytest/fixtures.py\", line 902, in call_fixture_func\n    fixture_result = fixturefunc(**kwargs)\n                     ^^^^^^^^^^^^^^^^^^^^^\n  File \"/Users/mx13/Desktop/tpay_automation/conftest.py\", line 92, in emulator_1\n    request.instance.driver_1 = webdriver.Remote(url, options=capabilities_options)\n                                ^^^^^^^^^^^^^^^^^^^^^^^^^^^^^^^^^^^^^^^^^^^^^^^^^^^\n  File \"/Users/mx13/Desktop/tpay_automation/myenv/lib/python3.11/site-packages/appium/webdriver/webdriver.py\", line 229, in __init__\n    super().__init__(\n  File \"/Users/mx13/Desktop/tpay_automation/myenv/lib/python3.11/site-packages/selenium/webdriver/remote/webdriver.py\", line 208, in __init__\n    self.start_session(capabilities)\n  File \"/Users/mx13/Desktop/tpay_automation/myenv/lib/python3.11/site-packages/appium/webdriver/webdriver.py\", line 318, in start_session\n    response = self.execute(RemoteCommand.NEW_SESSION, w3c_caps)\n               ^^^^^^^^^^^^^^^^^^^^^^^^^^^^^^^^^^^^^^^^^^^^^^^^^\n  File \"/Users/mx13/Desktop/tpay_automation/myenv/lib/python3.11/site-packages/selenium/webdriver/remote/webdriver.py\", line 347, in execute\n    self.error_handler.check_response(response)\n  File \"/Users/mx13/Desktop/tpay_automation/myenv/lib/python3.11/site-packages/selenium/webdriver/remote/errorhandler.py\", line 229, in check_response\n    raise exception_class(message, screen, stacktrace)\n"}, "start": 1701691662921, "stop": 1701691663990}], "afters": [{"name": "emulator_1::stop", "status": "passed", "start": 1701691664190, "stop": 1701691664191}], "start": 1701691662921, "stop": 1701691664191}